Traceback (most recent call last):
  File "C:\Users\User\AppData\Local\Packages\PythonSoftwareFoundation.Python.3.13_qbz5n2kfra8p0\LocalCache\local-packages\Python313\site-packages\jupyter_core\utils\__init__.py", line 154, in wrapped
    asyncio.get_running_loop()
    ~~~~~~~~~~~~~~~~~~~~~~~~^^
RuntimeError: no running event loop

During handling of the above exception, another exception occurred:

Traceback (most recent call last):
  File "C:\Users\User\AppData\Local\Packages\PythonSoftwareFoundation.Python.3.13_qbz5n2kfra8p0\LocalCache\local-packages\Python313\site-packages\jupyter_cache\executors\utils.py", line 58, in single_nb_execution
    executenb(
    ~~~~~~~~~^
        nb,
        ^^^
    ...<4 lines>...
        **kwargs,
        ^^^^^^^^^
    )
    ^
  File "C:\Users\User\AppData\Local\Packages\PythonSoftwareFoundation.Python.3.13_qbz5n2kfra8p0\LocalCache\local-packages\Python313\site-packages\nbclient\client.py", line 1319, in execute
    return NotebookClient(nb=nb, resources=resources, km=km, **kwargs).execute()
           ~~~~~~~~~~~~~~~~~~~~~~~~~~~~~~~~~~~~~~~~~~~~~~~~~~~~~~~~~~~~~~~~~~~^^
  File "C:\Users\User\AppData\Local\Packages\PythonSoftwareFoundation.Python.3.13_qbz5n2kfra8p0\LocalCache\local-packages\Python313\site-packages\jupyter_core\utils\__init__.py", line 158, in wrapped
    return loop.run_until_complete(inner)
           ~~~~~~~~~~~~~~~~~~~~~~~^^^^^^^
  File "C:\Program Files\WindowsApps\PythonSoftwareFoundation.Python.3.13_3.13.1520.0_x64__qbz5n2kfra8p0\Lib\asyncio\base_events.py", line 725, in run_until_complete
    return future.result()
           ~~~~~~~~~~~~~^^
  File "C:\Users\User\AppData\Local\Packages\PythonSoftwareFoundation.Python.3.13_qbz5n2kfra8p0\LocalCache\local-packages\Python313\site-packages\nbclient\client.py", line 709, in async_execute
    await self.async_execute_cell(
        cell, index, execution_count=self.code_cells_executed + 1
    )
  File "C:\Users\User\AppData\Local\Packages\PythonSoftwareFoundation.Python.3.13_qbz5n2kfra8p0\LocalCache\local-packages\Python313\site-packages\nbclient\client.py", line 1062, in async_execute_cell
    await self._check_raise_for_error(cell, cell_index, exec_reply)
  File "C:\Users\User\AppData\Local\Packages\PythonSoftwareFoundation.Python.3.13_qbz5n2kfra8p0\LocalCache\local-packages\Python313\site-packages\nbclient\client.py", line 918, in _check_raise_for_error
    raise CellExecutionError.from_cell_and_msg(cell, exec_reply_content)
nbclient.exceptions.CellExecutionError: An error occurred while executing the following cell:
------------------
# Example: Checking if a number is positive, negative, or zero and displaying an appropriate message

#Prompt the user to enter a number
given_number = input("Please enter any number: ")

# Uncomment and try these two variations as well.
# given_number = -5
# given_number = 0

# Check if the given number is greater than or equal to 0
if int(given_number) > 0:
    # If the condition is true, print a message indicating a positive number or zero
    print(given_number, "is Positive")
elif int(given_number) == 0:
        print(given_number, "is zero")
else:
    # If the condition is false, print a message indicating a negative number
    print(given_number, "is a Negative number")
------------------


[31m---------------------------------------------------------------------------[39m
[31mStdinNotImplementedError[39m                  Traceback (most recent call last)
[36mCell[39m[36m [39m[32mIn[9][39m[32m, line 4[39m
[32m      1[39m [38;5;66;03m# Example: Checking if a number is positive, negative, or zero and displaying an appropriate message[39;00m
[32m      2[39m 
[32m      3[39m [38;5;66;03m#Prompt the user to enter a number[39;00m
[32m----> [39m[32m4[39m given_number = [38;5;28;43minput[39;49m[43m([49m[33;43m"[39;49m[33;43mPlease enter any number: [39;49m[33;43m"[39;49m[43m)[49m
[32m      6[39m [38;5;66;03m# Uncomment and try these two variations as well.[39;00m
[32m      7[39m [38;5;66;03m# given_number = -5[39;00m
[32m      8[39m [38;5;66;03m# given_number = 0[39;00m
[32m      9[39m 
[32m     10[39m [38;5;66;03m# Check if the given number is greater than or equal to 0[39;00m
[32m     11[39m [38;5;28;01mif[39;00m [38;5;28mint[39m(given_number) > [32m0[39m:
[32m     12[39m     [38;5;66;03m# If the condition is true, print a message indicating a positive number or zero[39;00m

[36mFile [39m[32m~\AppData\Local\Packages\PythonSoftwareFoundation.Python.3.13_qbz5n2kfra8p0\LocalCache\local-packages\Python313\site-packages\ipykernel\kernelbase.py:1281[39m, in [36mKernel.raw_input[39m[34m(self, prompt)[39m
[32m   1279[39m [38;5;28;01mif[39;00m [38;5;129;01mnot[39;00m [38;5;28mself[39m._allow_stdin:
[32m   1280[39m     msg = [33m"[39m[33mraw_input was called, but this frontend does not support input requests.[39m[33m"[39m
[32m-> [39m[32m1281[39m     [38;5;28;01mraise[39;00m StdinNotImplementedError(msg)
[32m   1282[39m [38;5;28;01mreturn[39;00m [38;5;28mself[39m._input_request(
[32m   1283[39m     [38;5;28mstr[39m(prompt),
[32m   1284[39m     [38;5;28mself[39m._parent_ident[[33m"[39m[33mshell[39m[33m"[39m],
[32m   1285[39m     [38;5;28mself[39m.get_parent([33m"[39m[33mshell[39m[33m"[39m),
[32m   1286[39m     password=[38;5;28;01mFalse[39;00m,
[32m   1287[39m )

[31mStdinNotImplementedError[39m: raw_input was called, but this frontend does not support input requests.

